<?xml version="1.0" ?>
<sdf version="1.8">
    <world name="laberinto">
        <physics name="1ms" type="ignored">
            <max_step_size>0.001</max_step_size>
            <real_time_factor>1.0</real_time_factor>
        </physics>
        
        <!-- Plugins para cargar la escena -->
        <plugin
            filename="gz-sim-physics-system"
            name="gz::sim::systems::Physics">
        </plugin>
        <plugin
            filename="gz-sim-user-commands-system"
            name="gz::sim::systems::UserCommands">
        </plugin>
        <plugin
            filename="gz-sim-scene-broadcaster-system"
            name="gz::sim::systems::SceneBroadcaster">
        </plugin>
        <!-- -->

        <!-- Plugins de sensores -->
        <!-- IMU -->
        <plugin filename="gz-sim-imu-system"
            name="gz::sim::systems::Imu">
        </plugin>

        <!-- LiDAR -->
        <plugin
            filename="gz-sim-sensors-system"
            name="gz::sim::systems::Sensors">
            <render_engine>ogre2</render_engine>
        </plugin>
        <!-- -->

        <!-- Iluminación de la escena y del mundo -->
        <light type="directional" name="sun">
            <cast_shadows>true</cast_shadows>
            <pose>0 0 10 0 0 0</pose>
            <diffuse>0.8 0.8 0.8 1</diffuse>
            <specular>0.2 0.2 0.2 1</specular>
            <attenuation>
                <range>1000</range>
                <constant>0.9</constant>
                <linear>0.01</linear>
                <quadratic>0.001</quadratic>
            </attenuation>
            <direction>-0.5 0.1 -0.9</direction>
        </light>
        <!-- -->

        <!-- Suelo, necesario para no caer al vacío -->
        <model name="suelo">
            <static>true</static>
            <link name="link">
                <collision name="collision">
                <geometry>
                    <plane>
                    <normal>0 0 1</normal>
                    </plane>
                </geometry>
                </collision>
                <visual name="visual">
                <geometry>
                    <plane>
                    <normal>0 0 1</normal>
                    <size>100 100</size>
                    </plane>
                </geometry>
                <material>
                    <ambient>0.8 0.8 0.8 1</ambient>
                    <diffuse>0.8 0.8 0.8 1</diffuse>
                    <specular>0.8 0.8 0.8 1</specular>
                </material>
                </visual>
            </link>
        </model>
        <!-- -->

        <!-- Modelo del robot -->
        <model name='robot' canonical_link='chassis'>
            <pose relative_to='world'>-3.55 0 0 0 0 0</pose>
            
            <!-- Cuadro para colocar el LiDAR -->
            <frame name="lidar_frame" attached_to='chassis'>
                <!-- respecto del chassis -->
                <pose>0.8 0 0.5 0 0 0</pose> 
            </frame>

            <link name='chassis'>
                <pose relative_to='__model__'>0.5 0 0.4 0 0 0</pose>
                
                <!--Propiedades de inercia de la masa del link, matiz de inercia -->
                <!-- valores por defecto del tutorial -->
                <inertial> 
                    <mass>1.14395</mass>
                    <inertia>
                        <ixx>0.126164</ixx>
                        <ixy>0</ixy>
                        <ixz>0</ixz>
                        <iyy>0.416519</iyy>
                        <iyz>0</iyz>
                        <izz>0.481014</izz>
                    </inertia>
                </inertial>

                <!--Características visuales del robot -->
                <visual name='visual'>
                    <geometry>
                        <box>
                            <size>2.0 1.0 0.5</size> <!--en metros -->
                        </box>
                    </geometry>
                    <!-- Añadir color o material -->
                    <material>
                        <ambient>0.0 0.0 1.0 1</ambient>
                        <diffuse>0.0 0.0 1.0 1</diffuse>
                        <specular>0.0 0.0 1.0 1</specular>
                    </material>
                </visual>

                <!--Características de colisión del robot -->
                <collision name='collision'> 
                    <geometry>
                        <box>
                            <size>2.0 1.0 0.5</size>
                        </box>
                    </geometry>
                </collision>

                <!--Sensor IMU -->
                <sensor name="imu_sensor" type="imu">
                    <always_on>1</always_on>
                    <update_rate>1</update_rate>
                    <visualize>true</visualize>
                    <topic>imu</topic>
                </sensor>

                <!--Sensor LiDAR -->
                <sensor name='gpu_lidar' type='gpu_lidar'>
                    <pose relative_to='lidar_frame'>0 0 0 0 0 0</pose>
                    <topic>lidar</topic>
                    <update_rate>10</update_rate>
                    <ray>
                        <scan>
                            <horizontal>
                                <samples>640</samples>
                                <resolution>1</resolution>
                                <min_angle>-1.5708</min_angle>
                                <max_angle>1.5708</max_angle>
                            </horizontal>
                            <vertical>
                                <samples>1</samples>
                                <resolution>0.01</resolution>
                                <min_angle>0</min_angle>
                                <max_angle>0</max_angle>
                            </vertical>
                        </scan>
                        <range>
                            <min>0.08</min>
                            <max>10.0</max>
                            <resolution>0.01</resolution>
                        </range>
                    </ray>
                    <always_on>1</always_on>
                    <visualize>true</visualize>
                </sensor>
            </link>

            <!-- Rueda izquierda -->
            <link name='rueda_izq'>
                <!--ángulos en radianes-->
                <pose relative_to="chassis">-0.5 0.6 0 -1.5707 0 0</pose> 

                <inertial>
                    <mass>2</mass>
                    <inertia>
                        <ixx>0.145833</ixx>
                        <ixy>0</ixy>
                        <ixz>0</ixz>
                        <iyy>0.145833</iyy>
                        <iyz>0</iyz>
                        <izz>0.125</izz>
                    </inertia>
                </inertial>

                <visual name='visual'>
                    <geometry>
                        <cylinder>
                            <radius>0.4</radius>
                            <length>0.2</length>
                        </cylinder>
                    </geometry>
                    <material>
                        <ambient>1.0 0.0 0.0 1</ambient>
                        <diffuse>1.0 0.0 0.0 1</diffuse>
                        <specular>1.0 0.0 0.0 1</specular>
                    </material>
                </visual>

                <collision name='collision'>
                    <geometry>
                        <cylinder>
                            <radius>0.4</radius>
                            <length>0.2</length>
                        </cylinder>
                    </geometry>
                </collision>
            </link>

            <!-- Rueda derecha -->
            <link name='rueda_der'>
                
                <pose relative_to="chassis">-0.5 -0.6 0 -1.5707 0 0</pose>
                
                <inertial>
                    <mass>1</mass>
                    <inertia>
                        <ixx>0.145833</ixx>
                        <ixy>0</ixy>
                        <ixz>0</ixz>
                        <iyy>0.145833</iyy>
                        <iyz>0</iyz>
                        <izz>0.125</izz>
                    </inertia>
                </inertial>

                <visual name='visual'>
                    <geometry>
                        <cylinder>
                            <radius>0.4</radius>
                            <length>0.2</length>
                        </cylinder>
                    </geometry>
                    <material>
                        <ambient>1.0 0.0 0.0 1</ambient>
                        <diffuse>1.0 0.0 0.0 1</diffuse>
                        <specular>1.0 0.0 0.0 1</specular>
                    </material>
                </visual>

                <collision name='collision'>
                    <geometry>
                        <cylinder>
                            <radius>0.4</radius>
                            <length>0.2</length>
                        </cylinder>
                    </geometry>
                </collision>
            </link>

            <!-- Cuadro para la rueda giratoria -->
            <frame name="caster_frame" attached_to='chassis'>
                <pose>0.8 0 -0.2 0 0 0</pose>
            </frame>

            <!-- Rueda giratoria -->
            <link name='caster'>
                
                <pose relative_to='caster_frame'/>
                
                <inertial>
                    <mass>1</mass>
                    <inertia>
                        <ixx>0.1</ixx>
                        <ixy>0</ixy>
                        <ixz>0</ixz>
                        <iyy>0.1</iyy>
                        <iyz>0</iyz>
                        <izz>0.1</izz>
                    </inertia>
                </inertial>

                <visual name='visual'>
                    <geometry>
                        <sphere>
                            <radius>0.2</radius>
                        </sphere>
                    </geometry>
                    <material>
                        <ambient>0.0 1 0.0 1</ambient>
                        <diffuse>0.0 1 0.0 1</diffuse>
                        <specular>0.0 1 0.0 1</specular>
                    </material>
                </visual>

                <collision name='collision'>
                    <geometry>
                        <sphere>
                            <radius>0.2</radius>
                        </sphere>
                    </geometry>
                </collision>
            </link>


            <!--Articulación para rotar la rueda izquierda -->
            <joint name='rueda_izq_joint' type='revolute'> 
                <pose relative_to='rueda_izq'/>
                <parent>chassis</parent>
                <child>rueda_izq</child>
                <axis>
                    <!-- Dada la posición y orientación, giro sobre el eje y-->
                    <xyz expressed_in='__model__'>0 1 0</xyz> 
                    <limit>
                        <lower>-1.79769e+308</lower> <!--negativo infinito-->
                        <upper>1.79769e+308</upper> <!--positivo infinito-->
                    </limit>
                </axis>
            </joint>

            <!--Articulación para rotar la rueda derecha -->
            <joint name='rueda_der_joint' type='revolute'>
                <pose relative_to='rueda_der'/>
                <parent>chassis</parent>
                <child>rueda_der</child>
                <axis>
                    <!-- Dada la posición y orientación, giro sobre el eje y-->
                    <xyz expressed_in='__model__'>0 1 0</xyz>
                    <limit>
                        <lower>-1.79769e+308</lower> <!--negativo infinito-->
                        <upper>1.79769e+308</upper> <!--positivo infinito-->
                    </limit>
                </axis>
            </joint>

            <!--Articulación para la rueda giratoria -->
            <joint name='caster_wheel' type='ball'>
                <parent>chassis</parent>
                <child>caster</child>
            </joint>

            <!--Plugin para un control diferencial-->
            <plugin
                filename="gz-sim-diff-drive-system"
                name="gz::sim::systems::DiffDrive">
                <left_joint>rueda_izq_joint</left_joint>
                <right_joint>rueda_der_joint</right_joint>
                <wheel_separation>1.2</wheel_separation>
                <wheel_radius>0.4</wheel_radius>
                <odom_publish_frequency>1</odom_publish_frequency>
                <topic>cmd_vel</topic>
            </plugin>
        </model>
        <!-- -->

        <!--Pared izquierda-->
        <model name='pared_izq_1'>
            <static>true</static>
            <pose>6.03 0.12 0 0 0 0.54</pose>
            <link name='box'>
                <visual name='visual'>
                    <geometry>
                        <box>
                            <size>0.5 10.0 2.0</size>
                        </box>
                    </geometry>
                    <material>
                        <ambient>0.0 0.0 1.0 1</ambient>
                        <diffuse>0.0 0.0 1.0 1</diffuse>
                        <specular>0.0 0.0 1.0 1</specular>
                    </material>
                </visual>
                <collision name='collision'>
                    <geometry>
                        <box>
                            <size>0.5 10.0 2.0</size>
                        </box>
                    </geometry>
                </collision>
            </link>
        </model>
        <model name='pared_izq_2'>
            <static>true</static>
            <pose> 1.08 3.02 0 0 0 -1.3</pose>
            <link name='box'>
                <visual name='visual'>
                    <geometry>
                        <box>
                            <size>0.5 10.0 2.0</size>
                        </box>
                    </geometry>
                    <material>
                        <ambient>0.0 0.0 1.0 1</ambient>
                        <diffuse>0.0 0.0 1.0 1</diffuse>
                        <specular>0.0 0.0 1.0 1</specular>
                    </material>
                </visual>
                <collision name='collision'>
                    <geometry>
                        <box>
                            <size>0.5 10.0 2.0</size>
                        </box>
                    </geometry>
                </collision>
            </link>
        </model>

        <!--Pared derecha-->
        <model name='pared_der_1'>
            <static>true</static>
            <pose>-2.77 -1.98 0 0 0 -1.3</pose>
            <link name='box'>
                <visual name='visual'>
                    <geometry>
                        <box>
                            <size>0.5 10.0 2.0</size>
                        </box>
                    </geometry>
                    <material>
                        <ambient>0.0 0.0 1.0 1</ambient>
                        <diffuse>0.0 0.0 1.0 1</diffuse>
                        <specular>0.0 0.0 1.0 1</specular>
                    </material>
                </visual>
                <collision name='collision'>
                    <geometry>
                        <box>
                            <size>0.5 10.0 2.0</size>
                        </box>
                    </geometry>
                </collision>
            </link>
        </model>
        <model name='pared_der_2'>
            <static>true</static>
            <pose>4.2 -4.85 0 0 0 0.54</pose>
            <link name='box'>
                <visual name='visual'>
                    <geometry>
                        <box>
                            <size>0.5 10.0 2.0</size>
                        </box>
                    </geometry>
                    <material>
                        <ambient>0.0 0.0 1.0 1</ambient>
                        <diffuse>0.0 0.0 1.0 1</diffuse>
                        <specular>0.0 0.0 1.0 1</specular>
                    </material>
                </visual>
                <collision name='collision'>
                    <geometry>
                        <box>
                            <size>0.5 10.0 2.0</size>
                        </box>
                    </geometry>
                </collision>
            </link>
        </model>
    </world>
</sdf>